INFO:     Will watch for changes in these directories: ['/home/oskar/reparaturcafe']
INFO:     Uvicorn running on http://127.0.0.1:8000 (Press CTRL+C to quit)
INFO:     Started reloader process [17092] using WatchFiles
INFO:     Started server process [17094]
INFO:     Waiting for application startup.
INFO:     Application startup complete.
(trapped) error reading bcrypt version
Traceback (most recent call last):
  File "/home/oskar/reparaturcafe/api/.venv/lib/python3.12/site-packages/passlib/handlers/bcrypt.py", line 620, in _load_backend_mixin
    version = _bcrypt.__about__.__version__
              ^^^^^^^^^^^^^^^^^
AttributeError: module 'bcrypt' has no attribute '__about__'
ERROR:    Exception in ASGI application
Traceback (most recent call last):
  File "/home/oskar/reparaturcafe/api/.venv/lib/python3.12/site-packages/uvicorn/protocols/http/httptools_impl.py", line 419, in run_asgi
    result = await app(  # type: ignore[func-returns-value]
             ^^^^^^^^^^^^^^^^^^^^^^^^^^^^^^^^^^^^^^^^^^^^^^
  File "/home/oskar/reparaturcafe/api/.venv/lib/python3.12/site-packages/uvicorn/middleware/proxy_headers.py", line 84, in __call__
    return await self.app(scope, receive, send)
           ^^^^^^^^^^^^^^^^^^^^^^^^^^^^^^^^^^^^
  File "/home/oskar/reparaturcafe/api/.venv/lib/python3.12/site-packages/fastapi/applications.py", line 1054, in __call__
    await super().__call__(scope, receive, send)
  File "/home/oskar/reparaturcafe/api/.venv/lib/python3.12/site-packages/starlette/applications.py", line 123, in __call__
    await self.middleware_stack(scope, receive, send)
  File "/home/oskar/reparaturcafe/api/.venv/lib/python3.12/site-packages/starlette/middleware/errors.py", line 186, in __call__
    raise exc
  File "/home/oskar/reparaturcafe/api/.venv/lib/python3.12/site-packages/starlette/middleware/errors.py", line 164, in __call__
    await self.app(scope, receive, _send)
  File "/home/oskar/reparaturcafe/api/.venv/lib/python3.12/site-packages/starlette/middleware/exceptions.py", line 62, in __call__
    await wrap_app_handling_exceptions(self.app, conn)(scope, receive, send)
  File "/home/oskar/reparaturcafe/api/.venv/lib/python3.12/site-packages/starlette/_exception_handler.py", line 64, in wrapped_app
    raise exc
  File "/home/oskar/reparaturcafe/api/.venv/lib/python3.12/site-packages/starlette/_exception_handler.py", line 53, in wrapped_app
    await app(scope, receive, sender)
  File "/home/oskar/reparaturcafe/api/.venv/lib/python3.12/site-packages/starlette/routing.py", line 762, in __call__
    await self.middleware_stack(scope, receive, send)
  File "/home/oskar/reparaturcafe/api/.venv/lib/python3.12/site-packages/starlette/routing.py", line 782, in app
    await route.handle(scope, receive, send)
  File "/home/oskar/reparaturcafe/api/.venv/lib/python3.12/site-packages/starlette/routing.py", line 297, in handle
    await self.app(scope, receive, send)
  File "/home/oskar/reparaturcafe/api/.venv/lib/python3.12/site-packages/starlette/routing.py", line 77, in app
    await wrap_app_handling_exceptions(app, request)(scope, receive, send)
  File "/home/oskar/reparaturcafe/api/.venv/lib/python3.12/site-packages/starlette/_exception_handler.py", line 64, in wrapped_app
    raise exc
  File "/home/oskar/reparaturcafe/api/.venv/lib/python3.12/site-packages/starlette/_exception_handler.py", line 53, in wrapped_app
    await app(scope, receive, sender)
  File "/home/oskar/reparaturcafe/api/.venv/lib/python3.12/site-packages/starlette/routing.py", line 72, in app
    response = await func(request)
               ^^^^^^^^^^^^^^^^^^^
  File "/home/oskar/reparaturcafe/api/.venv/lib/python3.12/site-packages/fastapi/routing.py", line 299, in app
    raise e
  File "/home/oskar/reparaturcafe/api/.venv/lib/python3.12/site-packages/fastapi/routing.py", line 294, in app
    raw_response = await run_endpoint_function(
                   ^^^^^^^^^^^^^^^^^^^^^^^^^^^^
  File "/home/oskar/reparaturcafe/api/.venv/lib/python3.12/site-packages/fastapi/routing.py", line 191, in run_endpoint_function
    return await dependant.call(**values)
           ^^^^^^^^^^^^^^^^^^^^^^^^^^^^^^
  File "/home/oskar/reparaturcafe/api/routers/task.py", line 81, in get_task_by_id
    return TaskFull(**fake_tasks_db[str(task_id)])
           ^^^^^^^^^^^^^^^^^^^^^^^^^^^^^^^^^^^^^^^
  File "/home/oskar/reparaturcafe/api/.venv/lib/python3.12/site-packages/pydantic/main.py", line 164, in __init__
    __pydantic_self__.__pydantic_validator__.validate_python(data, self_instance=__pydantic_self__)
pydantic_core._pydantic_core.ValidationError: 1 validation error for TaskFull
supervisor_id
  Field required [type=missing, input_value={'id': 2, 'creation_date'... 'shelf_floor_no': None}, input_type=dict]
    For further information visit https://errors.pydantic.dev/2.5/v/missing
ERROR:    Exception in ASGI application
Traceback (most recent call last):
  File "/home/oskar/reparaturcafe/api/.venv/lib/python3.12/site-packages/uvicorn/protocols/http/httptools_impl.py", line 419, in run_asgi
    result = await app(  # type: ignore[func-returns-value]
             ^^^^^^^^^^^^^^^^^^^^^^^^^^^^^^^^^^^^^^^^^^^^^^
  File "/home/oskar/reparaturcafe/api/.venv/lib/python3.12/site-packages/uvicorn/middleware/proxy_headers.py", line 84, in __call__
    return await self.app(scope, receive, send)
           ^^^^^^^^^^^^^^^^^^^^^^^^^^^^^^^^^^^^
  File "/home/oskar/reparaturcafe/api/.venv/lib/python3.12/site-packages/fastapi/applications.py", line 1054, in __call__
    await super().__call__(scope, receive, send)
  File "/home/oskar/reparaturcafe/api/.venv/lib/python3.12/site-packages/starlette/applications.py", line 123, in __call__
    await self.middleware_stack(scope, receive, send)
  File "/home/oskar/reparaturcafe/api/.venv/lib/python3.12/site-packages/starlette/middleware/errors.py", line 186, in __call__
    raise exc
  File "/home/oskar/reparaturcafe/api/.venv/lib/python3.12/site-packages/starlette/middleware/errors.py", line 164, in __call__
    await self.app(scope, receive, _send)
  File "/home/oskar/reparaturcafe/api/.venv/lib/python3.12/site-packages/starlette/middleware/exceptions.py", line 62, in __call__
    await wrap_app_handling_exceptions(self.app, conn)(scope, receive, send)
  File "/home/oskar/reparaturcafe/api/.venv/lib/python3.12/site-packages/starlette/_exception_handler.py", line 64, in wrapped_app
    raise exc
  File "/home/oskar/reparaturcafe/api/.venv/lib/python3.12/site-packages/starlette/_exception_handler.py", line 53, in wrapped_app
    await app(scope, receive, sender)
  File "/home/oskar/reparaturcafe/api/.venv/lib/python3.12/site-packages/starlette/routing.py", line 762, in __call__
    await self.middleware_stack(scope, receive, send)
  File "/home/oskar/reparaturcafe/api/.venv/lib/python3.12/site-packages/starlette/routing.py", line 782, in app
    await route.handle(scope, receive, send)
  File "/home/oskar/reparaturcafe/api/.venv/lib/python3.12/site-packages/starlette/routing.py", line 297, in handle
    await self.app(scope, receive, send)
  File "/home/oskar/reparaturcafe/api/.venv/lib/python3.12/site-packages/starlette/routing.py", line 77, in app
    await wrap_app_handling_exceptions(app, request)(scope, receive, send)
  File "/home/oskar/reparaturcafe/api/.venv/lib/python3.12/site-packages/starlette/_exception_handler.py", line 64, in wrapped_app
    raise exc
  File "/home/oskar/reparaturcafe/api/.venv/lib/python3.12/site-packages/starlette/_exception_handler.py", line 53, in wrapped_app
    await app(scope, receive, sender)
  File "/home/oskar/reparaturcafe/api/.venv/lib/python3.12/site-packages/starlette/routing.py", line 72, in app
    response = await func(request)
               ^^^^^^^^^^^^^^^^^^^
  File "/home/oskar/reparaturcafe/api/.venv/lib/python3.12/site-packages/fastapi/routing.py", line 299, in app
    raise e
  File "/home/oskar/reparaturcafe/api/.venv/lib/python3.12/site-packages/fastapi/routing.py", line 294, in app
    raw_response = await run_endpoint_function(
                   ^^^^^^^^^^^^^^^^^^^^^^^^^^^^
  File "/home/oskar/reparaturcafe/api/.venv/lib/python3.12/site-packages/fastapi/routing.py", line 191, in run_endpoint_function
    return await dependant.call(**values)
           ^^^^^^^^^^^^^^^^^^^^^^^^^^^^^^
  File "/home/oskar/reparaturcafe/api/routers/task.py", line 81, in get_task_by_id
    return TaskFull(**fake_tasks_db[str(task_id)])
           ^^^^^^^^^^^^^^^^^^^^^^^^^^^^^^^^^^^^^^^
  File "/home/oskar/reparaturcafe/api/.venv/lib/python3.12/site-packages/pydantic/main.py", line 164, in __init__
    __pydantic_self__.__pydantic_validator__.validate_python(data, self_instance=__pydantic_self__)
pydantic_core._pydantic_core.ValidationError: 1 validation error for TaskFull
supervisor_id
  Field required [type=missing, input_value={'id': 2, 'creation_date'... 'shelf_floor_no': None}, input_type=dict]
    For further information visit https://errors.pydantic.dev/2.5/v/missing
ERROR:    Exception in ASGI application
Traceback (most recent call last):
  File "/home/oskar/reparaturcafe/api/.venv/lib/python3.12/site-packages/uvicorn/protocols/http/httptools_impl.py", line 419, in run_asgi
    result = await app(  # type: ignore[func-returns-value]
             ^^^^^^^^^^^^^^^^^^^^^^^^^^^^^^^^^^^^^^^^^^^^^^
  File "/home/oskar/reparaturcafe/api/.venv/lib/python3.12/site-packages/uvicorn/middleware/proxy_headers.py", line 84, in __call__
    return await self.app(scope, receive, send)
           ^^^^^^^^^^^^^^^^^^^^^^^^^^^^^^^^^^^^
  File "/home/oskar/reparaturcafe/api/.venv/lib/python3.12/site-packages/fastapi/applications.py", line 1054, in __call__
    await super().__call__(scope, receive, send)
  File "/home/oskar/reparaturcafe/api/.venv/lib/python3.12/site-packages/starlette/applications.py", line 123, in __call__
    await self.middleware_stack(scope, receive, send)
  File "/home/oskar/reparaturcafe/api/.venv/lib/python3.12/site-packages/starlette/middleware/errors.py", line 186, in __call__
    raise exc
  File "/home/oskar/reparaturcafe/api/.venv/lib/python3.12/site-packages/starlette/middleware/errors.py", line 164, in __call__
    await self.app(scope, receive, _send)
  File "/home/oskar/reparaturcafe/api/.venv/lib/python3.12/site-packages/starlette/middleware/exceptions.py", line 62, in __call__
    await wrap_app_handling_exceptions(self.app, conn)(scope, receive, send)
  File "/home/oskar/reparaturcafe/api/.venv/lib/python3.12/site-packages/starlette/_exception_handler.py", line 64, in wrapped_app
    raise exc
  File "/home/oskar/reparaturcafe/api/.venv/lib/python3.12/site-packages/starlette/_exception_handler.py", line 53, in wrapped_app
    await app(scope, receive, sender)
  File "/home/oskar/reparaturcafe/api/.venv/lib/python3.12/site-packages/starlette/routing.py", line 762, in __call__
    await self.middleware_stack(scope, receive, send)
  File "/home/oskar/reparaturcafe/api/.venv/lib/python3.12/site-packages/starlette/routing.py", line 782, in app
    await route.handle(scope, receive, send)
  File "/home/oskar/reparaturcafe/api/.venv/lib/python3.12/site-packages/starlette/routing.py", line 297, in handle
    await self.app(scope, receive, send)
  File "/home/oskar/reparaturcafe/api/.venv/lib/python3.12/site-packages/starlette/routing.py", line 77, in app
    await wrap_app_handling_exceptions(app, request)(scope, receive, send)
  File "/home/oskar/reparaturcafe/api/.venv/lib/python3.12/site-packages/starlette/_exception_handler.py", line 64, in wrapped_app
    raise exc
  File "/home/oskar/reparaturcafe/api/.venv/lib/python3.12/site-packages/starlette/_exception_handler.py", line 53, in wrapped_app
    await app(scope, receive, sender)
  File "/home/oskar/reparaturcafe/api/.venv/lib/python3.12/site-packages/starlette/routing.py", line 72, in app
    response = await func(request)
               ^^^^^^^^^^^^^^^^^^^
  File "/home/oskar/reparaturcafe/api/.venv/lib/python3.12/site-packages/fastapi/routing.py", line 315, in app
    content = await serialize_response(
              ^^^^^^^^^^^^^^^^^^^^^^^^^
  File "/home/oskar/reparaturcafe/api/.venv/lib/python3.12/site-packages/fastapi/routing.py", line 155, in serialize_response
    raise ResponseValidationError(
fastapi.exceptions.ResponseValidationError: 1 validation errors:
  {'type': 'missing', 'loc': ('response', 2, 'supervisor_id'), 'msg': 'Field required', 'input': {'id': 2, 'creation_date': '2024-07-01', 'device_name': 'Rasenmäher', 'device_manufacturer': 'Gardena', 'device_error_description': 'Springt nicht mehr an.', 'device_model': 'xyz', 'task_state': 'new', 'task_next_step': None, 'supervisor': 1, 'shelf_no': None, 'shelf_floor_no': None}, 'url': 'https://errors.pydantic.dev/2.5/v/missing'}

INFO:     Shutting down
INFO:     Waiting for application shutdown.
INFO:     Application shutdown complete.
INFO:     Finished server process [17094]
INFO:     Stopping reloader process [17092]
